<?xml version="1.0" ?>

<robot name="cf2">

  <properties arm="0.0397" kf="3.16e-10" km="7.94e-12" thrust2weight="2.25" max_speed_kmh="30" gnd_eff_coeff="11.36859" prop_radius="2.31348e-2" drag_coeff_xy="9.1785e-7" drag_coeff_z="10.311e-7" dw_coeff_1="2267.18" dw_coeff_2=".16" dw_coeff_3="-.11" />

  <link name="base_link"> 

    <inertial>
      <origin rpy="0 0 0" xyz="0 0 0"/>
      <mass value="0.027"/>
      <inertia ixx="2.8e-5" ixy="0.0" ixz="0.0" iyy="2.8e-5" iyz="0.0" izz="2.17e-5"/>
    </inertial>

    <!-- links>
      <carlos url="https://arxiv.org/pdf/1608.05786.pdf" />
      <julian url="https://www.research-collection.ethz.ch/handle/20.500.11850/214143" />
      <mit url="http://groups.csail.mit.edu/robotics-center/public_papers/Landry15.pdf" />
    </links -->

    <visual>
      <origin rpy="0 0 0" xyz="0 0 0"/>
      <geometry>
        <mesh filename="./body.obj" scale="1 1 1"/>
      </geometry> 
      <material name="grey">
        <color rgba=".5 .5 .5 1"/>
      </material> 
    </visual>

    <collision>
      <origin rpy="0 0 0" xyz="0 0 0"/>
      <geometry>
        <cylinder radius=".06" length=".025"/>
      </geometry>
    </collision>  

  </link>

  <link name="prop0_link">
    <inertial>
      <origin rpy="0 0 0" xyz="0.028 -0.028 0"/>
      <mass value="0"/>
      <inertia ixx="0" ixy="0" ixz="0" iyy="0" iyz="0" izz="0"/>
    </inertial>
    <visual>
      <origin rpy="0 0 0" xyz="0.0323 -0.0323 0.0132"/>
      <geometry>
          <mesh filename="./propeller0.obj"/>
      </geometry> 
    </visual>

  </link>
  <joint name="prop0_joint" type="fixed">
    <parent link="base_link"/>
    <child link="prop0_link"/>
  </joint>

  <link name="prop1_link">
    <inertial>
      <origin rpy="0 0 0" xyz="-0.028 -0.028 0"/>
      <mass value="0"/>
      <inertia ixx="0" ixy="0" ixz="0" iyy="0" iyz="0" izz="0"/>
    </inertial>
    <visual>
      <origin rpy="0 0 0" xyz="-0.0323 -0.0323 0.0132"/>
      <geometry>
          <mesh filename="./propeller1.obj"/>
      </geometry> 
    </visual>
  </link>
  <joint name="prop1_joint" type="fixed">
    <parent link="base_link"/>
    <child link="prop1_link"/>
  </joint>

  <link name="prop2_link">
    <inertial>
      <origin rpy="0 0 0" xyz="-0.028 0.028 0"/>
      <mass value="0"/>
      <inertia ixx="0" ixy="0" ixz="0" iyy="0" iyz="0" izz="0"/>
    </inertial>
    <visual>
      <origin rpy="0 0 0" xyz="-0.0323 0.0323 0.0132"/>
      <geometry>
          <mesh filename="./propeller2.obj"/>
      </geometry> 
    </visual>
  </link>
  <joint name="prop2_joint" type="fixed">
    <parent link="base_link"/>
    <child link="prop2_link"/>
  </joint>

  <link name="prop3_link">
    <inertial>
      <origin rpy="0 0 0" xyz="0.028 0.028 0"/>
      <mass value="0"/>
      <inertia ixx="0" ixy="0" ixz="0" iyy="0" iyz="0" izz="0"/>
    </inertial>
    <visual>
      <origin rpy="0 0 0" xyz="0.0323 0.0323 0.0132"/>
      <geometry>
          <mesh filename="./propeller3.obj"/>
      </geometry> 
    </visual>
  </link>
  <joint name="prop3_joint" type="fixed">
    <parent link="base_link"/>
    <child link="prop3_link"/>
  </joint>

  <link name="center_of_mass_link">
    <inertial>
      <origin rpy="0 0 0" xyz="0 0 0"/>
      <mass value="0"/>
      <inertia ixx="0" ixy="0" ixz="0" iyy="0" iyz="0" izz="0"/>
    </inertial>
  </link>
  <joint name="center_of_mass_joint" type="fixed">
    <parent link="base_link"/>
    <child link="center_of_mass_link"/>
  </joint>
  
  <link name="gripper_base">
    <visual>
      <geometry><box size="0.02 0.02 0.01"/></geometry>
      <material name="gray"/>
    </visual>
    <inertial>
      <mass value="0.0000"/>
      <inertia ixx="0" ixy="0" ixz="0"
               iyy="0" iyz="0"
               izz="0"/>
    </inertial>
  </link>
  <joint name="gripper_base_joint" type="fixed">
    <parent link="base_link"/>
    <child  link="gripper_base"/>
    <origin xyz="0 0 -0.01" rpy="0 0 0"/>
  </joint>
  
  <link name="gripper_left">
    <contact>
      <lateral_friction>2.0</lateral_friction>
      <spinning_friction>1.5</spinning_friction>
    </contact>
    <visual>
      <geometry><box size="0.005 0.01 0.025"/></geometry>
    </visual>
    <inertial>
      <mass value="0.001"/>
      <inertia ixx="1e-6" ixy="0" ixz="0"
               iyy="1e-6" iyz="0"
               izz="1e-7"/>
    </inertial>
    <collision>
      <origin rpy="0 0 0" xyz="0 0 0"/>
      <geometry>
        <box size="0.005 0.01 0.025"/>
      </geometry>
    </collision>
  </link>
  <joint name="joint_left_finger" type="prismatic">
    <parent link="gripper_base"/>
    <child  link="gripper_left"/>
    <origin xyz="0.02 0 -0.02" rpy="0 0 0"/>
    <axis  xyz="-1 0 0"/>
    <limit lower="0.0" upper="0.0155" effort="10.0" velocity="0.1"/>
    <dynamics>
      <damping>0</damping>
    </dynamics>
  </joint>

  <link name="gripper_right">
    <contact>
      <lateral_friction>2.0</lateral_friction>
      <spinning_friction>1.5</spinning_friction>
    </contact>
    <visual>
      <geometry><box size="0.005 0.01 0.025"/></geometry>
    </visual>
    <inertial>
      <mass value="0.001"/>
      <inertia ixx="1e-6" ixy="0" ixz="0"
               iyy="1e-6" iyz="0"
               izz="1e-7"/>
    </inertial>
    <collision>
      <origin rpy="0 0 0" xyz="0 0 0"/>
      <geometry>
        <box size="0.005 0.01 0.025"/>
      </geometry>
    </collision>
  </link>
  <joint name="joint_right_finger" type="prismatic">
    <parent link="gripper_base"/>
    <child  link="gripper_right"/>
    <origin xyz="-0.02 0 -0.02" rpy="0 0 0"/>
    <axis  xyz="1 0 0"/>
    <limit lower="0.0" upper="0.0155" effort="10.0" velocity="0.1"/>
    <dynamics>
      <damping>0</damping>
    </dynamics>
  </joint>  

</robot>

